Workbook

Sheet Conductor
B3: ..
B4: 22-ene | C4: 23-ene | D4: 24-ene | E4: 25-ene | F4: 26-ene | G4: 27-ene | H4: 28-ene | I4: 29-ene | J4: 30-ene | K4: 31-ene | L4: 01-feb | M4: 02-feb | N4: 03-feb | O4: 04-feb | P4: 05-feb | Q4: 06-feb | R4: 07-feb | S4: 08-feb | T4: 09-feb | U4: 10-feb | V4: 11-feb | W4: 12-feb | X4: 13-feb | Y4: 14-feb | Z4: 15-feb | AA4: 16-feb | AB4: 17-feb | AC4: 18-feb | AD4: 19-feb | AE4: 20-feb | AF4: 21-feb | AG4: Total general
A5: Etiquetas de fila | B5: Libre Compensatorio | C5: Ok | D5: Descanso | E5: Descanso | F5: Vacaciones | G5: Vacaciones | H5: Vacaciones | I5: Vacaciones | J5: Vacaciones | K5: Vacaciones | L5: Vacaciones | M5: Vacaciones | N5: Vacaciones | O5: Vacaciones | P5: Vacaciones | Q5: Vacaciones | R5: Vacaciones | S5: Vacaciones | T5: Vacaciones | U5: Vacaciones | V5: Vacaciones | W5: Vacaciones | X5: Vacaciones | Y5: Descanso | Z5: Descanso | AA5: Ok | AB5: Ok | AC5: Ok | AD5: Ok | AE5: Libre Compensatorio | AF5: Ok
A6: Andres Moya
A7: Suma de Despacho / Retiro | B7: 0 | C7: 0 | D7: 0 | E7: 0 | F7: 0 | G7: 0 | H7: 0 | I7: 0 | J7: 0 | K7: 0 | L7: 0 | M7: 0 | N7: 0 | O7: 0 | P7: 0 | Q7: 0 | R7: 0 | S7: 0 | T7: 0 | U7: 0 | V7: 0 | W7: 0 | X7: 0 | Y7: 0 | Z7: 0 | AA7: 0 | AB7: 20 | AC7: 34 | AD7: 22 | AE7: 0 | AF7: 0 | AG7: 76
A8: Suma de Entrada < 19:30 | B8: 0 | C8: 0 | D8: 0 | E8: 0 | F8: 0 | G8: 0 | H8: 0 | I8: 0 | J8: 0 | K8: 0 | L8: 0 | M8: 0 | N8: 0 | O8: 0 | P8: 0 | Q8: 0 | R8: 0 | S8: 0 | T8: 0 | U8: 0 | V8: 0 | W8: 0 | X8: 0 | Y8: 0 | Z8: 0 | AA8: 0 | AB8: 0 | AC8: 0 | AD8: 0 | AE8: 0 | AF8: 0 | AG8: 0
A9: Suma de Salida > 19:30 | B9: 0 | C9: 0 | D9: 0 | E9: 0 | F9: 0 | G9: 0 | H9: 0 | I9: 0 | J9: 0 | K9: 0 | L9: 0 | M9: 0 | N9: 0 | O9: 0 | P9: 0 | Q9: 0 | R9: 0 | S9: 0 | T9: 0 | U9: 0 | V9: 0 | W9: 0 | X9: 0 | Y9: 0 | Z9: 0 | AA9: 0 | AB9: 0 | AC9: 0 | AD9: 0 | AE9: 0 | AF9: 0 | AG9: 0
A10: Suma de Feria Semana 01 | B10: 0 | C10: 0 | D10: 0 | E10: 0 | F10: 0 | G10: 0 | H10: 0 | I10: 0 | J10: 0 | K10: 0 | L10: 0 | M10: 0 | N10: 0 | O10: 0 | P10: 0 | Q10: 0 | R10: 0 | S10: 0 | T10: 0 | U10: 0 | V10: 0 | W10: 0 | X10: 0 | Y10: 0 | Z10: 0 | AA10: 0 | AB10: 0 | AC10: 1 | AD10: 0 | AE10: 0 | AF10: 0 | AG10: 1
A11: Suma de Feria Semana 02 | B11: 0 | C11: 0 | D11: 0 | E11: 0 | F11: 0 | G11: 0 | H11: 0 | I11: 0 | J11: 0 | K11: 0 | L11: 0 | M11: 0 | N11: 0 | O11: 0 | P11: 0 | Q11: 0 | R11: 0 | S11: 0 | T11: 0 | U11: 0 | V11: 0 | W11: 0 | X11: 0 | Y11: 0 | Z11: 0 | AA11: 0 | AB11: 1 | AC11: 0 | AD11: 1 | AE11: 0 | AF11: 0 | AG11: 2
A12: Suma de Fuera Radio Normal | B12: 0 | C12: 2 | D12: 0 | E12: 0 | F12: 0 | G12: 0 | H12: 0 | I12: 0 | J12: 0 | K12: 0 | L12: 0 | M12: 0 | N12: 0 | O12: 0 | P12: 0 | Q12: 0 | R12: 0 | S12: 0 | T12: 0 | U12: 0 | V12: 0 | W12: 0 | X12: 0 | Y12: 0 | Z12: 0 | AA12: 0 | AB12: 0 | AC12: 0 | AD12: 0 | AE12: 0 | AF12: 0 | AG12: 2
A13: Suma de Fuera Radio V Región | B13: 0 | C13: 0 | D13: 0 | E13: 0 | F13: 0 | G13: 0 | H13: 0 | I13: 0 | J13: 0 | K13: 0 | L13: 0 | M13: 0 | N13: 0 | O13: 0 | P13: 0 | Q13: 0 | R13: 0 | S13: 0 | T13: 0 | U13: 0 | V13: 0 | W13: 0 | X13: 0 | Y13: 0 | Z13: 0 | AA13: 0 | AB13: 0 | AC13: 0 | AD13: 0 | AE13: 0 | AF13: 0 | AG13: 0
A14: Suma de Sabado | B14: 0 | C14: 0 | D14: 0 | E14: 0 | F14: 0 | G14: 0 | H14: 0 | I14: 0 | J14: 0 | K14: 0 | L14: 0 | M14: 0 | N14: 0 | O14: 0 | P14: 0 | Q14: 0 | R14: 0 | S14: 0 | T14: 0 | U14: 0 | V14: 0 | W14: 0 | X14: 0 | Y14: 0 | Z14: 0 | AA14: 0 | AB14: 0 | AC14: 0 | AD14: 0 | AE14: 0 | AF14: 1 | AG14: 1
A15: Suma de Aux Sabado Semana 02 | B15: 0 | C15: 0 | D15: 0 | E15: 0 | F15: 0 | G15: 0 | H15: 0 | I15: 0 | J15: 0 | K15: 0 | L15: 0 | M15: 0 | N15: 0 | O15: 0 | P15: 0 | Q15: 0 | R15: 0 | S15: 0 | T15: 0 | U15: 0 | V15: 0 | W15: 0 | X15: 0 | Y15: 0 | Z15: 0 | AA15: 0 | AB15: 0 | AC15: 0 | AD15: 0 | AE15: 0 | AF15: 0 | AG15: 0
A16: Suma de Domingo | B16: 0 | C16: 0 | D16: 0 | E16: 0 | F16: 0 | G16: 0 | H16: 0 | I16: 0 | J16: 0 | K16: 0 | L16: 0 | M16: 0 | N16: 0 | O16: 0 | P16: 0 | Q16: 0 | R16: 0 | S16: 0 | T16: 0 | U16: 0 | V16: 0 | W16: 0 | X16: 0 | Y16: 0 | Z16: 0 | AA16: 0 | AB16: 0 | AC16: 0 | AD16: 0 | AE16: 0 | AF16: 0 | AG16: 0
A17: Suma de Aux Domingo Semana 02 | B17: 0 | C17: 0 | D17: 0 | E17: 0 | F17: 0 | G17: 0 | H17: 0 | I17: 0 | J17: 0 | K17: 0 | L17: 0 | M17: 0 | N17: 0 | O17: 0 | P17: 0 | Q17: 0 | R17: 0 | S17: 0 | T17: 0 | U17: 0 | V17: 0 | W17: 0 | X17: 0 | Y17: 0 | Z17: 0 | AA17: 0 | AB17: 0 | AC17: 0 | AD17: 0 | AE17: 0 | AF17: 0 | AG17: 0
A18: Suma de Viajes Por Cliente | B18: 0 | C18: 0 | D18: 0 | E18: 0 | F18: 0 | G18: 0 | H18: 0 | I18: 0 | J18: 0 | K18: 0 | L18: 0 | M18: 0 | N18: 0 | O18: 0 | P18: 0 | Q18: 0 | R18: 0 | S18: 0 | T18: 0 | U18: 0 | V18: 0 | W18: 0 | X18: 0 | Y18: 0 | Z18: 0 | AA18: 0 | AB18: 0 | AC18: 0 | AD18: 0 | AE18: 0 | AF18: 2 | AG18: 2
... A46: Total Suma de Fosa | B46: 0 | C46: 0 | D46: 0 | E46: 0 | F46: 0 | G46: 0 | H46: 0 | I46: 0 | J46: 0 | K46: 0 | L46: 0 | M46: 0 | N46: 0 | O46: 0 | P46: 0 | Q46: 0 | R46: 0 | S46: 0 | T46: 0 | U46: 0 | V46: 0 | W46: 0 | X46: 0 | Y46: 0 | Z46: 0 | AA46: 0 | AB46: 0 | AC46: 0 | AD46: 0 | AE46: 0 | AF46: 0 | AG46: 0

Sheet Auxiliar
B3: ..
B4: 22-ene | F4: 23-ene | I4: 24-ene | K4: 25-ene | M4: 26-ene | Q4: 27-ene | U4: 28-ene | Z4: 29-ene | AE4: 30-ene | AI4: 31-ene | AM4: 01-feb | AQ4: 02-feb | AV4: 03-feb | AZ4: 04-feb | BE4: 05-feb | BI4: 06-feb | BM4: 07-feb | BQ4: 08-feb | BU4: 09-feb | BZ4: 10-feb | CD4: 11-feb | CH4: 12-feb | CL4: 13-feb | CQ4: 14-feb | CT4: 15-feb | CW4: 16-feb | DB4: 17-feb | DF4: 18-feb | DJ4: 19-feb | DM4: 20-feb | DQ4: 21-feb | DT4: Total general
A5: Etiquetas de fila | B5: Libre Compensatorio | C5: Ok | D5: Sin Producción | E5: Servicios | F5: Libre Compensatorio | G5: Ok | H5: Servicios | I5: Ok | J5: Descanso | K5: Ok | L5: Descanso | M5: Ok | N5: Sin Producción | O5: Vacaciones | P5: Servicios | Q5: Libre Compensatorio | R5: Ok | S5: Vacaciones | T5: Servicios | U5: Libre Compensatorio | V5: Ok | W5: Sin Producción | X5: Vacaciones | Y5: Servicios | Z5: Libre Compensatorio | AA5: Ok | AB5: Sin Producción | AC5: Vacaciones | AD5: Servicios | AE5: Libre Compensatorio | AF5: Ok | AG5: Vacaciones | AH5: Servicios | AI5: Ok | AJ5: Vacaciones | AK5: Descanso | AL5: Servicios | AM5: Ok | AN5: Vacaciones | AO5: Descanso | AP5: Servicios | AQ5: Libre Compensatorio | AR5: Ok | AS5: Sin Producción | AT5: Vacaciones | AU5: Servicios | AV5: Libre Compensatorio | AW5: Ok | AX5: Vacaciones | AY5: Servicios | AZ5: Libre Compensatorio | BA5: Ok | BB5: Sin Producción | BC5: Vacaciones | BD5: Servicios | BE5: Libre Compensatorio | BF5: Ok | BG5: Vacaciones | BH5: Servicios | BI5: Ok | BJ5: Sin Producción | BK5: Vacaciones | BL5: Servicios | BM5: Ok | BN5: Vacaciones | BO5: Descanso | BP5: Servicios | BQ5: Ok | BR5: Vacaciones | BS5: Descanso | BT5: Servicios | BU5: Libre Compensatorio | BV5: Ok | BW5: Sin Producción | BX5: Vacaciones | BY5: Servicios | BZ5: Libre Compensatorio | CA5: Ok | CB5: Vacaciones | CC5: Servicios | CD5: Libre Compensatorio | CE5: Ok | CF5: Vacaciones | CG5: Servicios | CH5: Libre Compensatorio | CI5: Ok | CJ5: Vacaciones | CK5: Servicios | CL5: Ok | CM5: Sin Producción | CN5: Vacaciones | CO5: Servicios | CP5: Libre Cumpleaños | CQ5: Ok | CR5: Descanso | CS5: Servicios | CT5: Ok | CU5: Descanso | CV5: Servicios | CW5: Libre Compensatorio | CX5: Ok | CY5: Sin Producción | CZ5: Vacaciones | DA5: Servicios | DB5: Libre Compensatorio | DC5: Ok | DD5: Vacaciones | DE5: Servicios | DF5: Libre Compensatorio | DG5: Ok | DH5: Vacaciones | DI5: Servicios | DJ5: Ok | DK5: Vacaciones | DL5: Servicios | DM5: Libre Compensatorio | DN5: Ok | DO5: Vacaciones | DP5: Servicios | DQ5: Ok | DR5: Vacaciones | DS5: Descanso
A6: Alejandro Escobar
A7: Suma de Despacho / Retiro | C7: 44 | G7: 32 | I7: 0 | K7: 0 | M7: 13 | R7: 36 | V7: 40 | AA7: 2 | AF7: 39 | AK7: 0 | AO7: 0 | AR7: 0 | AV7: 0 | BA7: 40 | BF7: 24 | BI7: 30 | BM7: 0 | BQ7: 0 | BW7: 0 | CA7: 36 | CD7: 0 | CI7: 36 | CL7: 47 | CQ7: 0 | CT7: 0 | CX7: 0 | DC7: 20 | DF7: 0 | DJ7: 38 | DN7: 18 | DQ7: 0 | DT7: 495
A8: Suma de Entrada < 19:30 | C8: 0 | G8: 0 | I8: 0 | K8: 0 | M8: 0 | R8: 0 | V8: 0 | AA8: 0 | AF8: 0 | AK8: 0 | AO8: 0 | AR8: 0 | AV8: 0 | BA8: 0 | BF8: 0 | BI8: 0 | BM8: 0 | BQ8: 0 | BW8: 0 | CA8: 0 | CD8: 0 | CI8: 0 | CL8: 0 | CQ8: 0 | CT8: 0 | CX8: 0 | DC8: 0 | DF8: 0 | DJ8: 0 | DN8: 0 | DQ8: 0 | DT8: 0
A9: Suma de Salida > 19:30 | C9: 0 | G9: 2 | I9: 0 | K9: 0 | M9: 0 | R9: 0 | V9: 0 | AA9: 0 | AF9: 0 | AK9: 0 | AO9: 0 | AR9: 0 | AV9: 0 | BA9: 0 | BF9: 1 | BI9: 0 | BM9: 0 | BQ9: 0 | BW9: 0 | CA9: 0 | CD9: 0 | CI9: 0 | CL9: 0 | CQ9: 0 | CT9: 0 | CX9: 0 | DC9: 0 | DF9: 0 | DJ9: 0 | DN9: 0 | DQ9: 0 | DT9: 3
A10: Suma de Feria Semana 01 | C10: 2 | G10: 2 | I10: 0 | K10: 0 | M10: 0 | R10: 1 | V10: 1 | AA10: 0 | AF10: 1 | AK10: 0 | AO10: 0 | AR10: 0 | AV10: 0 | BA10: 1 | BF10: 0 | BI10: 0 | BM10: 0 | BQ10: 0 | BW10: 0 | CA10: 1 | CD10: 0 | CI10: 1 | CL10: 1 | CQ10: 0 | CT10: 0 | CX10: 0 | DC10: 1 | DF10: 0 | DJ10: 1 | DN10: 1 | DQ10: 0 | DT10: 14
A11: Suma de Feria Semana 02 | C11: 0 | G11: 0 | I11: 0 | K11: 0 | M11: 0 | R11: 0 | V11: 0 | AA11: 0 | AF11: 0 | AK11: 0 | AO11: 0 | AR11: 0 | AV11: 0 | BA11: 0 | BF11: 1 | BI11: 1 | BM11: 0 | BQ11: 0 | BW11: 0 | CA11: 0 | CD11: 0 | CI11: 0 | CL11: 0 | CQ11: 0 | CT11: 0 | CX11: 0 | DC11: 0 | DF11: 0 | DJ11: 0 | DN11: 0 | DQ11: 0 | DT11: 2
A12: Suma de Fuera Radio Normal | C12: 0 | G12: 0 | I12: 0 | K12: 1 | M12: 0 | R12: 0 | V12: 0 | AA12: 0 | AF12: 0 | AK12: 0 | AO12: 0 | AR12: 0 | AV12: 0 | BA12: 0 | BF12: 0 | BI12: 0 | BM12: 0 | BQ12: 0 | BW12: 0 | CA12: 0 | CD12: 0 | CI12: 0 | CL12: 0 | CQ12: 0 | CT12: 0 | CX12: 0 | DC12: 0 | DF12: 0 | DJ12: 0 | DN12: 0 | DQ12: 0 | DT12: 1
A13: Suma de Fuera Radio V Región | C13: 0 | G13: 0 | I13: 0 | K13: 0 | M13: 0 | R13: 0 | V13: 0 | AA13: 0 | AF13: 0 | AK13: 0 | AO13: 0 | AR13: 0 | AV13: 0 | BA13: 0 | BF13: 0 | BI13: 0 | BM13: 0 | BQ13: 0 | BW13: 0 | CA13: 1 | CD13: 0 | CI13: 1 | CL13: 0 | CQ13: 0 | CT13: 0 | CX13: 0 | DC13: 0 | DF13: 0 | DJ13: 0 | DN13: 0 | DQ13: 0 | DT13: 2
A14: Suma de Sabado | C14: 0 | G14: 0 | I14: 1 | K14: 0 | M14: 0 | R14: 0 | V14: 0 | AA14: 0 | AF14: 0 | AK14: 0 | AO14: 0 | AR14: 0 | AV14: 0 | BA14: 0 | BF14: 0 | BI14: 0 | BM14: 1 | BQ14: 0 | BW14: 0 | CA14: 0 | CD14: 0 | CI14: 0 | CL14: 0 | CQ14: 1 | CT14: 0 | CX14: 0 | DC14: 0 | DF14: 0 | DJ14: 0 | DN14: 0 | DQ14: 1 | DT14: 4
A15: Suma de Aux Sabado Semana 02 | C15: 0 | G15: 0 | I15: 0 | K15: 0 | M15: 0 | R15: 0 | V15: 0 | AA15: 0 | AF15: 0 | AK15: 0 | AO15: 0 | AR15: 0 | AV15: 0 | BA15: 0 | BF15: 0 | BI15: 0 | BM15: 0 | BQ15: 0 | BW15: 0 | CA15: 0 | CD15: 0 | CI15: 0 | CL15: 0 | CQ15: 0 | CT15: 0 | CX15: 0 | DC15: 0 | DF15: 0 | DJ15: 0 | DN15: 0 | DQ15: 1 | DT15: 1
A16: Suma de Domingo | C16: 0 | G16: 0 | I16: 0 | K16: 1 | M16: 0 | R16: 0 | V16: 0 | AA16: 0 | AF16: 0 | AK16: 0 | AO16: 0 | AR16: 0 | AV16: 0 | BA16: 0 | BF16: 0 | BI16: 0 | BM16: 0 | BQ16: 1 | BW16: 0 | CA16: 0 | CD16: 0 | CI16: 0 | CL16: 0 | CQ16: 0 | CT16: 1 | CX16: 0 | DC16: 0 | DF16: 0 | DJ16: 0 | DN16: 0 | DQ16: 0 | DT16: 3
A17: Suma de Aux Domingo Semana 02 | C17: 0 | G17: 0 | I17: 0 | K17: 0 | M17: 0 | R17: 0 | V17: 0 | AA17: 0 | AF17: 0 | AK17: 0 | AO17: 0 | AR17: 0 | AV17: 0 | BA17: 0 | BF17: 0 | BI17: 0 | BM17: 0 | BQ17: 0 | BW17: 0 | CA17: 0 | CD17: 0 | CI17: 0 | CL17: 0 | CQ17: 0 | CT17: 0 | CX17: 0 | DC17: 0 | DF17: 0 | DJ17: 0 | DN17: 0 | DQ17: 0 | DT17: 0
A18: Suma de Viajes Por Cliente | C18: 0 | G18: 0 | I18: 0 | K18: 2 | M18: 0 | R18: 0 | V18: 1 | AA18: 0 | AF18: 0 | AK18: 0 | AO18: 0 | AR18: 0 | AV18: 0 | BA18: 0 | BF18: 0 | BI18: 0 | BM18: 0 | BQ18: 13 | BW18: 0 | CA18: 1 | CD18: 0 | CI18: 0 | CL18: 0 | CQ18: 4 | CT18: 6 | CX18: 0 | DC18: 0 | DF18: 0 | DJ18: 2 | DN18: 0 | DQ18: 1 | DT18: 30
... A26: Suma de Fosa | C26: 0 | G26: 0 | I26: 0 | K26: 0 | M26: 0 | R26: 0 | V26: 0 | AA26: 0 | AF26: 0 | AK26: 0 | AO26: 0 | AR26: 0 | AV26: 0 | BA26: 0 | BF26: 0 | BI26: 0 | BM26: 0 | BQ26: 0 | BW26: 0 | CA26: 0 | CD26: 0 | CI26: 0 | CL26: 0 | CQ26: 0 | CT26: 0 | CX26: 0 | DC26: 0 | DF26: 0 | DJ26: 0 | DN26: 0 | DQ26: 0 | DT26: 0
A27: Gonzalo Gonzalez
A28: Suma de Despacho / Retiro | E28: 0 | H28: 0 | J28: 0 | L28: 0 | P28: 0 | T28: 0 | Y28: 0 | AD28: 0 | AH28: 0 | AK28: 0 | AO28: 0 | AU28: 0 | AY28: 0 | BD28: 0 | BH28: 0 | BL28: 0 | BO28: 0 | BS28: 0 | BY28: 0 | CC28: 0 | CG28: 0 | CK28: 0 | CO28: 0 | CR28: 0 | CU28: 0 | DA28: 0 | DE28: 0 | DI28: 0 | DL28: 0 | DP28: 0 | DS28: 0 | DT28: 0
A29: Suma de Entrada < 19:30 | E29: 0 | H29: 0 | J29: 0 | L29: 0 | P29: 0 | T29: 0 | Y29: 0 | AD29: 0 | AH29: 0 | AK29: 0 | AO29: 0 | AU29: 0 | AY29: 0 | BD29: 0 | BH29: 0 | BL29: 0 | BO29: 0 | BS29: 0 | BY29: 0 | CC29: 0 | CG29: 0 | CK29: 0 | CO29: 0 | CR29: 0 | CU29: 0 | DA29: 0 | DE29: 0 | DI29: 0 | DL29: 0 | DP29: 0 | DS29: 0 | DT29: 0
A30: Suma de Salida > 19:30 | E30: 0 | H30: 0 | J30: 0 | L30: 0 | P30: 0 | T30: 0 | Y30: 0 | AD30: 0 | AH30: 0 | AK30: 0 | AO30: 0 | AU30: 0 | AY30: 0 | BD30: 0 | BH30: 0 | BL30: 0 | BO30: 0 | BS30: 0 | BY30: 0 | CC30: 0 | CG30: 0 | CK30: 0 | CO30: 0 | CR30: 0 | CU30: 0 | DA30: 0 | DE30: 0 | DI30: 0 | DL30: 0 | DP30: 0 | DS30: 0 | DT30: 0
A31: Suma de Feria Semana 01 | E31: 0 | H31: 0 | J31: 0 | L31: 0 | P31: 0 | T31: 0 | Y31: 0 | AD31: 0 | AH31: 0 | AK31: 0 | AO31: 0 | AU31: 0 | AY31: 0 | BD31: 0 | BH31: 0 | BL31: 0 | BO31: 0 | BS31: 0 | BY31: 0 | CC31: 0 | CG31: 0 | CK31: 0 | CO31: 0 | CR31: 0 | CU31: 0 | DA31: 0 | DE31: 0 | DI31: 0 | DL31: 0 | DP31: 0 | DS31: 0 | DT31: 0
A32: Suma de Feria Semana 02 | E32: 0 | H32: 0 | J32: 0 | L32: 0 | P32: 0 | T32: 0 | Y32: 0 | AD32: 0 | AH32: 0 | AK32: 0 | AO32: 0 | AU32: 0 | AY32: 0 | BD32: 0 | BH32: 0 | BL32: 0 | BO32: 0 | BS32: 0 | BY32: 0 | CC32: 0 | CG32: 0 | CK32: 0 | CO32: 0 | CR32: 0 | CU32: 0 | DA32: 0 | DE32: 0 | DI32: 0 | DL32: 0 | DP32: 0 | DS32: 0 | DT32: 0
A33: Suma de Fuera Radio Normal | E33: 0 | H33: 0 | J33: 0 | L33: 0 | P33: 0 | T33: 0 | Y33: 0 | AD33: 0 | AH33: 0 | AK33: 0 | AO33: 0 | AU33: 0 | AY33: 0 | BD33: 0 | BH33: 0 | BL33: 0 | BO33: 0 | BS33: 0 | BY33: 0 | CC33: 0 | CG33: 0 | CK33: 0 | CO33: 0 | CR33: 0 | CU33: 0 | DA33: 0 | DE33: 0 | DI33: 0 | DL33: 0 | DP33: 0 | DS33: 0 | DT33: 0
A34: Suma de Fuera Radio V Región | E34: 0 | H34: 0 | J34: 0 | L34: 0 | P34: 0 | T34: 0 | Y34: 0 | AD34: 0 | AH34: 0 | AK34: 0 | AO34: 0 | AU34: 0 | AY34: 0 | BD34: 0 | BH34: 0 | BL34: 0 | BO34: 0 | BS34: 0 | BY34: 0 | CC34: 0 | CG34: 0 | CK34: 0 | CO34: 0 | CR34: 0 | CU34: 0 | DA34: 0 | DE34: 0 | DI34: 0 | DL34: 0 | DP34: 0 | DS34: 0 | DT34: 0
A35: Suma de Sabado | E35: 0 | H35: 0 | J35: 0 | L35: 0 | P35: 0 | T35: 0 | Y35: 0 | AD35: 0 | AH35: 0 | AK35: 0 | AO35: 0 | AU35: 0 | AY35: 0 | BD35: 0 | BH35: 0 | BL35: 0 | BO35: 0 | BS35: 0 | BY35: 0 | CC35: 0 | CG35: 0 | CK35: 0 | CO35: 0 | CR35: 0 | CU35: 0 | DA35: 0 | DE35: 0 | DI35: 0 | DL35: 0 | DP35: 0 | DS35: 0 | DT35: 0
A36: Suma de Aux Sabado Semana 02 | E36: 0 | H36: 0 | J36: 0 | L36: 0 | P36: 0 | T36: 0 | Y36: 0 | AD36: 0 | AH36: 0 | AK36: 0 | AO36: 0 | AU36: 0 | AY36: 0 | BD36: 0 | BH36: 0 | BL36: 0 | BO36: 0 | BS36: 0 | BY36: 0 | CC36: 0 | CG36: 0 | CK36: 0 | CO36: 0 | CR36: 0 | CU36: 0 | DA36: 0 | DE36: 0 | DI36: 0 | DL36: 0 | DP36: 0 | DS36: 0 | DT36: 0
A37: Suma de Domingo | E37: 0 | H37: 0 | J37: 0 | L37: 0 | P37: 0 | T37: 0 | Y37: 0 | AD37: 0 | AH37: 0 | AK37: 0 | AO37: 0 | AU37: 0 | AY37: 0 | BD37: 0 | BH37: 0 | BL37: 0 | BO37: 0 | BS37: 0 | BY37: 0 | CC37: 0 | CG37: 0 | CK37: 0 | CO37: 0 | CR37: 0 | CU37: 0 | DA37: 0 | DE37: 0 | DI37: 0 | DL37: 0 | DP37: 0 | DS37: 0 | DT37: 0
A38: Suma de Aux Domingo Semana 02 | E38: 0 | H38: 0 | J38: 0 | L38: 0 | P38: 0 | T38: 0 | Y38: 0 | AD38: 0 | AH38: 0 | AK38: 0 | AO38: 0 | AU38: 0 | AY38: 0 | BD38: 0 | BH38: 0 | BL38: 0 | BO38: 0 | BS38: 0 | BY38: 0 | CC38: 0 | CG38: 0 | CK38: 0 | CO38: 0 | CR38: 0 | CU38: 0 | DA38: 0 | DE38: 0 | DI38: 0 | DL38: 0 | DP38: 0 | DS38: 0 | DT38: 0
A39: Suma de Viajes Por Cliente | E39: 0 | H39: 0 | J39: 0 | L39: 0 | P39: 0 | T39: 0 | Y39: 0 | AD39: 0 | AH39: 0 | AK39: 0 | AO39: 0 | AU39: 0 | AY39: 0 | BD39: 0 | BH39: 0 | BL39: 0 | BO39: 0 | BS39: 0 | BY39: 0 | CC39: 0 | CG39: 0 | CK39: 0 | CO39: 0 | CR39: 0 | CU39: 0 | DA39: 0 | DE39: 0 | DI39: 0 | DL39: 0 | DP39: 0 | DS39: 0 | DT39: 0
... A47: Suma de Fosa | E47: 0 | H47: 0 | J47: 0 | L47: 0 | P47: 0 | T47: 0 | Y47: 0 | AD47: 0 | AH47: 0 | AK47: 0 | AO47: 0 | AU47: 0 | AY47: 0 | BD47: 0 | BH47: 0 | BL47: 0 | BO47: 0 | BS47: 0 | BY47: 0 | CC47: 0 | CG47: 0 | CK47: 0 | CO47: 0 | CR47: 0 | CU47: 0 | DA47: 0 | DE47: 0 | DI47: 0 | DL47: 0 | DP47: 0 | DS47: 0 | DT47: 0
A48: Hugo Troncoso
A49: Suma de Despacho / Retiro | C49: 32 | G49: 36 | I49: 0 | K49: 0 | M49: 5 | R49: 29 | V49: 42 | AA49: 26 | AF49: 26 | AK49: 0 | AO49: 0 | AS49: 0 | AW49: 45 | AZ49: 0 | BF49: 37 | BI49: 36 | BM49: 0 | BQ49: 0 | BW49: 0 | CA49: 16 | CE49: 36 | CH49: 0 | CM49: 0 | CR49: 0 | CU49: 0 | CX49: 12 | DC49: 33 | DF49: 0 | DJ49: 20 | DN49: 22 | DQ49: 0 | DT49: 453
A50: Suma de Entrada < 19:30 | C50: 0 | G50: 0 | I50: 0 | K50: 0 | M50: 0 | R50: 0 | V50: 0 | AA50: 0 | AF50: 0 | AK50: 0 | AO50: 0 | AS50: 0 | AW50: 0 | AZ50: 0 | BF50: 0 | BI50: 0 | BM50: 0 | BQ50: 0 | BW50: 0 | CA50: 0 | CE50: 0 | CH50: 0 | CM50: 0 | CR50: 0 | CU50: 0 | CX50: 0 | DC50: 0 | DF50: 0 | DJ50: 0 | DN50: 0 | DQ50: 0 | DT50: 0
A51: Suma de Salida > 19:30 | C51: 0 | G51: 0 | I51: 0 | K51: 0 | M51: 0 | R51: 0 | V51: 0 | AA51: 0 | AF51: 0 | AK51: 0 | AO51: 0 | AS51: 0 | AW51: 0 | AZ51: 0 | BF51: 1 | BI51: 0 | BM51: 0 | BQ51: 0 | BW51: 0 | CA51: 0 | CE51: 0 | CH51: 0 | CM51: 0 | CR51: 0 | CU51: 0 | CX51: 0 | DC51: 0 | DF51: 0 | DJ51: 0 | DN51: 0 | DQ51: 0 | DT51: 1
A52: Suma de Feria Semana 01 | C52: 1 | G52: 2 | I52: 0 | K52: 0 | M52: 0 | R52: 0 | V52: 1 | AA52: 0 | AF52: 0 | AK52: 0 | AO52: 0 | AS52: 0 | AW52: 1 | AZ52: 0 | BF52: 1 | BI52: 1 | BM52: 0 | BQ52: 0 | BW52: 0 | CA52: 1 | CE52: 1 | CH52: 0 | CM52: 0 | CR52: 0 | CU52: 0 | CX52: 0 | DC52: 1 | DF52: 0 | DJ52: 1 | DN52: 1 | DQ52: 0 | DT52: 12
A53: Suma de Feria Semana 02 | C53: 0 | G53: 0 | I53: 0 | K53: 0 | M53: 0 | R53: 1 | V53: 0 | AA53: 1 | AF53: 1 | AK53: 0 | AO53: 0 | AS53: 0 | AW53: 0 | AZ53: 0 | BF53: 0 | BI53: 0 | BM53: 0 | BQ53: 0 | BW53: 0 | CA53: 0 | CE53: 0 | CH53: 0 | CM53: 0 | CR53: 0 | CU53: 0 | CX53: 0 | DC53: 0 | DF53: 0 | DJ53: 0 | DN53: 0 | DQ53: 0 | DT53: 3
A54: Suma de Fuera Radio Normal | C54: 0 | G54: 0 | I54: 0 | K54: 1 | M54: 1 | R54: 1 | V54: 0 | AA54: 1 | AF54: 0 | AK54: 0 | AO54: 0 | AS54: 0 | AW54: 1 | AZ54: 0 | BF54: 0 | BI54: 0 | BM54: 0 | BQ54: 0 | BW54: 0 | CA54: 0 | CE54: 0 | CH54: 0 | CM54: 0 | CR54: 0 | CU54: 0 | CX54: 1 | DC54: 0 | DF54: 0 | DJ54: 0 | DN54: 0 | DQ54: 0 | DT54: 6
A55: Suma de Fuera Radio V Región | C55: 0 | G55: 0 | I55: 0 | K55: 0 | M55: 0 | R55: 0 | V55: 0 | AA55: 0 | AF55: 0 | AK55: 0 | AO55: 0 | AS55: 0 | AW55: 0 | AZ55: 0 | BF55: 0 | BI55: 0 | BM55: 0 | BQ55: 0 | BW55: 0 | CA55: 1 | CE55: 0 | CH55: 0 | CM55: 0 | CR55: 0 | CU55: 0 | CX55: 0 | DC55: 0 | DF55: 0 | DJ55: 0 | DN55: 0 | DQ55: 0 | DT55: 1
A56: Suma de Sabado | C56: 0 | G56: 0 | I56: 1 | K56: 0 | M56: 0 | R56: 0 | V56: 0 | AA56: 0 | AF56: 0 | AK56: 0 | AO56: 0 | AS56: 0 | AW56: 0 | AZ56: 0 | BF56: 0 | BI56: 0 | BM56: 1 | BQ56: 0 | BW56: 0 | CA56: 0 | CE56: 0 | CH56: 0 | CM56: 0 | CR56: 0 | CU56: 0 | CX56: 0 | DC56: 0 | DF56: 0 | DJ56: 0 | DN56: 0 | DQ56: 1 | DT56: 3
...

Sheet Base Datos
A1: Operador | B1: Auxiliar | C1: Cod. Usuario | D1: Fecha Inicial | E1: Fecha Final | F1: Duración | G1: Estado | H1: Despacho / Retiro | I1: Entrada < 19:30 | J1: Salida > 19:30 | K1: Feria Semana 01 | L1: Feria Semana 02 | M1: Fuera Radio Normal | N1: Fuera Radio V Región | O1: Sabado | P1: Domingo | Q1: Viajes Por Cliente | R1: Sábado > 16:00 | S1: Domingo > 16:00 | T1: URL | U1: Secado | V1: Evento | W1: Punto de Agua | X1: Basurero Grande | Y1: Basurero chico | Z1: Fosa | AA1: Aux Sabado Semana 02 | AB1: Aux Domingo Semana 02
A2: Cristian Valdivia | B2: Hugo Troncoso | C2: OP-S-100 | D2: 45769 | E2: 45769 | F2: 50 | G2: Ok | H2: 30 | I2: 0 | J2: 0 | K2: 1 | L2: 0 | M2: 0 | N2: 0 | O2: 0 | P2: 0 | Q2: 0 | R2: 0 | S2: 0 | T2: https://www.clickideacore.com/ClickHTML5/Visit.aspx?ID=//52DAEwASwAzADMAMAA2ADMAMgAyADQASQBEAEUAQQAC=&Tipo=2&ST=1&nLang=0 | U2: 0 | V2: 0 | W2: 0 | X2: 0 | Y2: 0 | Z2: 0 | AA2: 0 | AB2: 0
A3: Daniel Peña | B3: Michael Suarez | C3: OP-DYR-004 | D3: 45769 | E3: 45769 | F3: 23 | G3: Ok | H3: 20 | I3: 0 | J3: 0 | K3: 1 | L3: 0 | M3: 0 | N3: 0 | O3: 0 | P3: 0 | Q3: 0 | R3: 0 | S3: 0 | T3: https://www.clickideacore.com/ClickHTML5/Visit.aspx?ID=//56DAEwASwAzADMAMAA2ADIAMwA4ADkASQBEAEUAQQAE=&Tipo=2&ST=1&nLang=0 | U3: 0 | V3: 16 | W3: 0 | X3: 0 | Y3: 0 | Z3: 0 | AA3: 0 | AB3: 0
A4: Eduardo Soto | B4: Alejandro Escobar | C4: OP-S-200 | D4: 45769 | E4: 45769 | F4: 33 | G4: Ok | H4: 28 | I4: 0 | J4: 0 | K4: 1 | L4: 0 | M4: 0 | N4: 0 | O4: 0 | P4: 0 | Q4: 0 | R4: 0 | S4: 0 | T4: https://www.clickideacore.com/ClickHTML5/Visit.aspx?ID=//5DDAEwASwAzADMAMAA2ADIAMQAzADYASQBEAEUAQQAB=&Tipo=2&ST=1&nLang=0 | U4: 0 | V4: 49 | W4: 2 | X4: 0 | Y4: 15 | Z4: 0 | AA4: 0 | AB4: 0
A5: Gerardo Cartes | B5: Yosman Perez | C5: OP-S-076 | D5: 45769 | E5: 45769 | F5: 43 | G5: Ok | H5: 14 | I5: 0 | J5: 0 | K5: 0 | L5: 1 | M5: 0 | N5: 0 | O5: 0 | P5: 0 | Q5: 0 | R5: 0 | S5: 0 | T5: https://www.clickideacore.com/ClickHTML5/Visit.aspx?ID=//57DAEwASwAzADMAMAA2ADEAOAA4ADAASQBEAEUAQQA3=&Tipo=2&ST=1&nLang=0 | U5: 0 | V5: 28 | W5: 0 | X5: 0 | Y5: 0 | Z5: 0 | AA5: 0 | AB5: 0
A6: Luis Alvarez | B6: Wilmer Villa | C6: OP-DYR-005 | D6: 45769 | E6: 45769 | F6: 22 | G6: Ok | H6: 19 | I6: 0 | J6: 0 | K6: 1 | L6: 0 | M6: 0 | N6: 0 | O6: 0 | P6: 0 | Q6: 0 | R6: 0 | S6: 0 | T6: https://www.clickideacore.com/ClickHTML5/Visit.aspx?ID=//57DAEwASwAzADMAMAA2ADMAOQAwADAASQBEAEUAQQAB=&Tipo=2&ST=1&nLang=0 | U6: 0 | V6: 0 | W6: 2 | X6: 0 | Y6: 0 | Z6: 0 | AA6: 0 | AB6: 0
A7: Claudio Garrido | B7: Andres Moya | C7: OP-S-005 | D7: 45769 | E7: 45769 | F7: 53 | G7: Ok | H7: 1 | I7: 0 | J7: 0 | K7: 0 | L7: 0 | M7: 0 | N7: 0 | O7: 0 | P7: 0 | Q7: 0 | R7: 0 | S7: 0 | T7: https://www.clickideacore.com/ClickHTML5/Visit.aspx?ID=//5BDAEwASwAzADMAMAAxADIAMQA1ADYASQBEAEUAQQA9=&Tipo=2&ST=1&nLang=0 | U7: 0 | V7: 16 | W7: 0 | X7: 0 | Y7: 0 | Z7: 0 | AA7: 0 | AB7: 0
A8: Jeremias Cerda | B8: N/A | C8: 0 | D8: 45769 | E8: 45769 | F8: 0 | G8: Libre Compensatorio | H8: 0 | I8: 0 | J8: 0 | K8: 0 | L8: 0 | M8: 0 | N8: 0 | O8: 0 | P8: 0 | Q8: 0 | R8: 0 | S8: 0 | T8: 0 | U8: 0 | V8: 0 | W8: 0 | X8: 0 | Y8: 0 | Z8: 0 | AA8: 0 | AB8: 0
A9: Albert Riveros | B9: N/A | C9: 0 | D9: 45769 | E9: 45769 | F9: 0 | G9: Licencia Medica | H9: 0 | I9: 0 | J9: 0 | K9: 0 | L9: 0 | M9: 0 | N9: 0 | O9: 0 | P9: 0 | Q9: 0 | R9: 0 | S9: 0 | T9: 0 | U9: 0 | V9: 0 | W9: 0 | X9: 0 | Y9: 0 | Z9: 0 | AA9: 0 | AB9: 0
A10: Francisco Cuevas | B10: N/A | C10: 0 | D10: 45769 | E10: 45769 | F10: 0 | G10: Licencia Medica | H10: 0 | I10: 0 | J10: 0 | K10: 0 | L10: 0 | M10: 0 | N10: 0 | O10: 0 | P10: 0 | Q10: 0 | R10: 0 | S10: 0 | T10: 0 | U10: 0 | V10: 0 | W10: 0 | X10: 0 | Y10: 0 | Z10: 0 | AA10: 0 | AB10: 0
A11: N/A | B11: Gonzalo Gonzalez | C11: 0 | D11: 45769 | E11: 45769 | F11: 0 | G11: Licencia Medica | H11: 0 | I11: 0 | J11: 0 | K11: 0 | L11: 0 | M11: 0 | N11: 0 | O11: 0 | P11: 0 | Q11: 0 | R11: 0 | S11: 0 | T11: 0 | U11: 0 | V11: 0 | W11: 0 | X11: 0 | Y11: 0 | Z11: 0 | AA11: 0 | AB11: 0
A12: Claudio Garrido | B12: Jeremias Cerda | C12: OP-S-005 | D12: 45770 | E12: 45770 | F12: 25 | G12: Ok | H12: 26 | I12: 0 | J12: 0 | K12: 1 | L12: 0 | M12: 0 | N12: 0 | O12: 0 | P12: 0 | Q12: 0 | R12: 0 | S12: 0 | T12: https://www.clickideacore.com/ClickHTML5/Visit.aspx?ID=//53DAEwASwAzADMAMAA4ADMANQA1ADMASQBEAEUAQQA1=&Tipo=2&ST=1&nLang=0 | U12: 0 | V12: 22 | W12: 0 | X12: 0 | Y12: 0 | Z12: 0 | AA12: 0 | AB12: 0
A13: Daniel Peña | B13: Michael Suarez | C13: OP-DYR-004 | D13: 45770 | E13: 45770 | F13: 23 | G13: Ok | H13: 25 | I13: 0 | J13: 0 | K13: 1 | L13: 0 | M13: 0 | N13: 0 | O13: 0 | P13: 0 | Q13: 0 | R13: 0 | S13: 0 | T13: https://www.clickideacore.com/ClickHTML5/Visit.aspx?ID=//5EDAEwASwAzADMAMAA5ADAAMgA3ADUASQBEAEUAQQA1=&Tipo=2&ST=1&nLang=0 | U13: 0 | V13: 15 | W13: 0 | X13: 0 | Y13: 0 | Z13: 0 | AA13: 0 | AB13: 0
A14: Eduardo Soto | B14: Alejandro Escobar | C14: OP-S-200 | D14: 45770 | E14: 45770 | F14: 18 | G14: Ok | H14: 28 | I14: 0 | J14: 0 | K14: 1 | L14: 0 | M14: 0 | N14: 0 | O14: 0 | P14: 0 | Q14: 0 | R14: 0 | S14: 0 | T14: https://www.clickideacore.com/ClickHTML5/Visit.aspx?ID=//59DAEwASwAzADMAMAA4ADgANQAwADUASQBEAEUAQQA7=&Tipo=2&ST=1&nLang=0 | U14: 0 | V14: 22 | W14: 0 | X14: 0 | Y14: 0 | Z14: 0 | AA14: 0 | AB14: 0
A15: Gerardo Cartes | B15: Yosman Perez | C15: OP-S-076 | D15: 45770 | E15: 45770 | F15: 30 | G15: Ok | H15: 11 | I15: 0 | J15: 0 | K15: 0 | L15: 1 | M15: 1 | N15: 0 | O15: 0 | P15: 0 | Q15: 0 | R15: 0 | S15: 0 | T15: https://www.clickideacore.com/ClickHTML5/Visit.aspx?ID=//56DAEwASwAzADMAMAA4ADUANAA3ADMASQBEAEUAQQA6=&Tipo=2&ST=1&nLang=0 | U15: 0 | V15: 14 | W15: 0 | X15: 0 | Y15: 0 | Z15: 0 | AA15: 0 | AB15: 0
A16: Luis Alvarez | B16: Wilmer Villa | C16: OP-DYR-005 | D16: 45770 | E16: 45770 | F16: 27 | G16: Ok | H16: 39 | I16: 0 | J16: 0 | K16: 1 | L16: 0 | M16: 0 | N16: 0 | O16: 0 | P16: 0 | Q16: 0 | R16: 0 | S16: 0 | T16: https://www.clickideacore.com/ClickHTML5/Visit.aspx?ID=//5ADAEwASwAzADMAMAA5ADIANgA1ADIASQBEAEUAQQA1=&Tipo=2&ST=1&nLang=0 | U16: 0 | V16: 23 | W16: 0 | X16: 0 | Y16: 0 | Z16: 0 | AA16: 0 | AB16: 0
A17: Andres Moya | B17: Edgar Benavides | C17: 0 | D17: 45770 | E17: 45770 | F17: 27 | G17: Ok | H17: 0 | I17: 0 | J17: 0 | K17: 0 | L17: 0 | M17: 0 | N17: 0 | O17: 0 | P17: 0 | Q17: 0 | R17: 0 | S17: 0 | T17: https://www.clickideacore.com/ClickHTML5/Visit.aspx?ID=//5ADAEwASwAzADMAMAA5ADIANgA1ADIASQBEAEUAQQA1=&Tipo=2&ST=1&nLang=0 | U17: 0 | V17: 20 | W17: 0 | X17: 0 | Y17: 0 | Z17: 0 | AA17: 0 | AB17: 0
A18: Cristian Valdivia | B18: Hugo Troncoso | C18: 0 | D18: 45770 | E18: 45770 | F18: 0 | G18: Libre Compensatorio | H18: 0 | I18: 0 | J18: 0 | K18: 0 | L18: 0 | M18: 0 | N18: 0 | O18: 0 | P18: 0 | Q18: 0 | R18: 0 | S18: 0 | T18: 0 | U18: 0 | V18: 0 | W18: 0 | X18: 0 | Y18: 0 | Z18: 0 | AA18: 0 | AB18: 0
A19: Albert Riveros | B19: N/A | C19: 0 | D19: 45770 | E19: 45770 | F19: 0 | G19: Licencia Medica | H19: 0 | I19: 0 | J19: 0 | K19: 0 | L19: 0 | M19: 0 | N19: 0 | O19: 0 | P19: 0 | Q19: 0 | R19: 0 | S19: 0 | T19: 0 | U19: 0 | V19: 0 | W19: 0 | X19: 0 | Y19: 0 | Z19: 0 | AA19: 0 | AB19: 0
A20: Francisco Cuevas | B20: N/A | C20: 0 | D20: 45770 | E20: 45770 | F20: 0 | G20: Licencia Medica | H20: 0 | I20: 0 | J20: 0 | K20: 0 | L20: 0 | M20: 0 | N20: 0 | O20: 0 | P20: 0 | Q20: 0 | R20: 0 | S20: 0 | T20: 0 | U20: 0 | V20: 0 | W20: 0 | X20: 0 | Y20: 0 | Z20: 0 | AA20: 0 | AB20: 0
A21: N/A | B21: Gonzalo Gonzalez | C21: 0 | D21: 45770 | E21: 45770 | F21: 0 | G21: Licencia Medica | H21: 0 | I21: 0 | J21: 0 | K21: 0 | L21: 0 | M21: 0 | N21: 0 | O21: 0 | P21: 0 | Q21: 0 | R21: 0 | S21: 0 | T21: 0 | U21: 0 | V21: 0 | W21: 0 | X21: 0 | Y21: 0 | Z21: 0 | AA21: 0 | AB21: 0
A22: Andres Moya | B22: Andres Moya | C22: OP-DYR-011 | D22: 45771 | E22: 45771 | F22: 45 | G22: Ok | H22: 0 | I22: 0 | J22: 0 | K22: 0 | L22: 0 | M22: 0 | N22: 0 | O22: 0 | P22: 0 | Q22: 0 | R22: 0 | S22: 0 | T22: https://www.clickideacore.com/ClickHTML5/Visit.aspx?ID=//59DAEwASwAzADMAMQAwADMANAAxADEASQBEAEUAQQA1=&Tipo=2&ST=1&nLang=0 | U22: 0 | V22: 20 | W22: 0 | X22: 0 | Y22: 0 | Z22: 0 | AA22: 0 | AB22: 0
A23: Claudio Garrido | B23: Jeremias Cerda | C23: OP-S-005 | D23: 45771 | E23: 45771 | F23: 36 | G23: Ok | H23: 25 | I23: 0 | J23: 0 | K23: 0 | L23: 1 | M23: 0 | N23: 0 | O23: 0 | P23: 0 | Q23: 0 | R23: 0 | S23: 0 | T23: https://www.clickideacore.com/ClickHTML5/Visit.aspx?ID=//50DAEwASwAzADMAMQAwADkAOAAyADEASQBEAEUAQQAA=&Tipo=2&ST=1&nLang=0 | U23: 0 | V23: 13 | W23: 0 | X23: 0 | Y23: 0 | Z23: 0 | AA23: 0 | AB23: 0
A24: Cristian Valdivia | B24: Hugo Troncoso | C24: OP-S-100 | D24: 45771 | E24: 45771 | F24: 34 | G24: Ok | H24: 30 | I24: 0 | J24: 0 | K24: 1 | L24: 0 | M24: 0 | N24: 0 | O24: 0 | P24: 0 | Q24: 0 | R24: 0 | S24: 0 | T24: https://www.clickideacore.com/ClickHTML5/Visit.aspx?ID=//52DAEwASwAzADMAMQAwADYAOQAxADcASQBEAEUAQQAC=&Tipo=2&ST=1&nLang=0 | U24: 0 | V24: 22 | W24: 0 | X24: 0 | Y24: 0 | Z24: 0 | AA24: 0 | AB24: 0
A25: Daniel Peña | B25: Michael Suarez | C25: OP-DYR-004 | D25: 45771 | E25: 45771 | F25: 21 | G25: Ok | H25: 35 | I25: 0 | J25: 0 | K25: 1 | L25: 0 | M25: 0 | N25: 0 | O25: 0 | P25: 0 | Q25: 0 | R25: 0 | S25: 0 | T25: https://www.clickideacore.com/ClickHTML5/Visit.aspx?ID=//51DAEwASwAzADMAMQAwADYANAAyADYASQBEAEUAQQAF=&Tipo=2&ST=1&nLang=0 | U25: 0 | V25: 20 | W25: 0 | X25: 0 | Y25: 0 | Z25: 0 | AA25: 0 | AB25: 0
A26: Luis Alvarez | B26: Wilmer Villa | C26: OP-DYR-005 | D26: 45771 | E26: 45771 | F26: 19 | G26: Ok | H26: 19 | I26: 0 | J26: 0 | K26: 1 | L26: 0 | M26: 0 | N26: 0 | O26: 0 | P26: 0 | Q26: 0 | R26: 0 | S26: 0 | T26: https://www.clickideacore.com/ClickHTML5/Visit.aspx?ID=//5EDAEwASwAzADMAMQAxADAANQAzADEASQBEAEUAQQAA=&Tipo=2&ST=1&nLang=0 | U26: 0 | V26: 14 | W26: 0 | X26: 0 | Y26: 0 | Z26: 0 | AA26: 0 | AB26: 0
A27: Eduardo Soto | B27: Alejandro Escobar | C27: OP-S-200 | D27: 45771 | E27: 45771 | F27: 33 | G27: Ok | H27: 28 | I27: 0 | J27: 0 | K27: 1 | L27: 0 | M27: 0 | N27: 0 | O27: 0 | P27: 0 | Q27: 0 | R27: 0 | S27: 0 | T27: https://www.clickideacore.com/ClickHTML5/Visit.aspx?ID=//5DDAEwASwAzADMAMAA2ADIAMQAzADYASQBEAEUAQQAB=&Tipo=2&ST=1&nLang=0 | U27: 0 | V27: 49 | W27: 2 | X27: 0 | Y27: 0 | Z27: 0 | AA27: 0 | AB27: 0
A28: Gerardo Cartes | B28: Yosman Perez | C28: 0 | D28: 45771 | E28: 45771 | F28: 0 | G28: Libre Compensatorio | H28: 0 | I28: 0 | J28: 0 | K28: 0 | L28: 0 | M28: 0 | N28: 0 | O28: 0 | P28: 0 | Q28: 0 | R28: 0 | S28: 0 | T28: 0 | U28: 0 | V28: 0 | W28: 0 | X28: 0 | Y28: 0 | Z28: 0 | AA28: 0 | AB28: 0
A29: Albert Riveros | B29: N/A | C29: 0 | D29: 45771 | E29: 45771 | F29: 0 | G29: Licencia Medica | H29: 0 | I29: 0 | J29: 0 | K29: 0 | L29: 0 | M29: 0 | N29: 0 | O29: 0 | P29: 0 | Q29: 0 | R29: 0 | S29: 0 | T29: 0 | U29: 0 | V29: 0 | W29: 0 | X29: 0 | Y29: 0 | Z29: 0 | AA29: 0 | AB29: 0
A30: Francisco Cuevas | B30: N/A | C30: 0 | D30: 45771 | E30: 45771 | F30: 0 | G30: Licencia Medica | H30: 0 | I30: 0 | J30: 0 | K30: 0 | L30: 0 | M30: 0 | N30: 0 | O30: 0 | P30: 0 | Q30: 0 | R30: 0 | S30: 0 | T30: 0 | U30: 0 | V30: 0 | W30: 0 | X30: 0 | Y30: 0 | Z30: 0 | AA30: 0 | AB30: 0
A31: N/A | B31: Gonzalo Gonzalez | C31: 0 | D31: 45771 | E31: 45771 | F31: 0 | G31: Licencia Medica | H31: 0 | I31: 0 | J31: 0 | K31: 0 | L31: 0 | M31: 0 | N31: 0 | O31: 0 | P31: 0 | Q31: 0 | R31: 0 | S31: 0 | T31: 0 | U31: 0 | V31: 0 | W31: 0 | X31: 0 | Y31: 0 | Z31: 0 | AA31: 0 | AB31: 0
A32: Andres Moya | B32: Wilmer Villa | C32: OP-DYR-011 | D32: 45772 | E32: 45772 | F32: 37 | G32: Ok | H32: 29 | I32: 0 | J32: 0 | K32: 1 | L32: 0 | M32: 1 | N32: 0 | O32: 0 | P32: 0 | Q32: 1 | R32: 0 | S32: 0 | T32: https://www.clickideacore.com/ClickHTML5/Visit.aspx?ID=//5CDAEwASwAzADMAMQAyADkAOQA5ADAASQBEAEUAQQAA=&Tipo=2&ST=1&nLang=0 | U32: 0 | V32: 3 | W32: 0 | X32: 0 | Y32: 0 | Z32: 0 | AA32: 0 | AB32: 0
A33: Cristian Valdivia | B33: Hugo Troncoso | C33: OP-S-100 | D33: 45772 | E33: 45772 | F33: 56 | G33: Ok | H33: 18 | I33: 0 | J33: 0 | K33: 1 | L33: 0 | M33: 0 | N33: 0 | O33: 0 | P33: 0 | Q33: 0 | R33: 0 | S33: 0 | T33: https://www.clickideacore.com/ClickHTML5/Visit.aspx?ID=//59DAEwASwAzADMAMQAzADAAOQAxADAASQBEAEUAQQA2=&Tipo=2&ST=1&nLang=0 | U33: 0 | V33: 0 | W33: 0 | X33: 0 | Y33: 0 | Z33: 0 | AA33: 0 | AB33: 0
A34: Gerardo Cartes | B34: Yosman Perez | C34: OP-S-076 | D34: 45772 | E34: 45772 | F34: 46 | G34: Ok | H34: 24 | I34: 0 | J34: 0 | K34: 0 | L34: 1 | M34: 0 | N34: 0 | O34: 0 | P34: 0 | Q34: 0 | R34: 0 | S34: 0 | T34: https://www.clickideacore.com/ClickHTML5/Visit.aspx?ID=//5EDAEwASwAzADMAMQAzADIAMwAzADAASQBEAEUAQQA0=&Tipo=2&ST=1&nLang=0 | U34: 0 | V34: 15 | W34: 0 | X34: 0 | Y34: 0 | Z34: 0 | AA34: 0 | AB34: 0
A35: Claudio Garrido | B35: Jeremias Cerda | C35: OP-S-076 | D35: 45772 | E35: 45772 | F35: 46 | G35: Ok | H35: 28 | I35: 0 | J35: 0 | K35: 0 | L35: 1 | M35: 0 | N35: 0 | O35: 0 | P35: 0 | Q35: 0 | R35: 0 | S35: 0 | T35: https://www.clickideacore.com/ClickHTML5/Visit.aspx?ID=//5EDAEwASwAzADMAMQAzADIAMwAzADAASQBEAEUAQQA0=&Tipo=2&ST=1&nLang=0 | U35: 0 | V35: 15 | W35: 0 | X35: 0 | Y35: 0 | Z35: 0 | AA35: 0 | AB35: 0
A36: Luis Alvarez | B36: N/A | C36: 0 | D36: 45772 | E36: 45772 | F36: 0 | G36: Libre Compensatorio | H36: 0 | I36: 0 | J36: 0 | K36: 0 | L36: 0 | M36: 0 | N36: 0 | O36: 0 | P36: 0 | Q36: 0 | R36: 0 | S36: 0 | T36: 0 | U36: 0 | V36: 0 | W36: 0 | X36: 0 | Y36: 0 | Z36: 0 | AA36: 0 | AB36: 0
A37: Daniel Peña | B37: Michael Suarez | C37: 0 | D37: 45772 | E37: 45772 | F37: 0 | G37: Libre Compensatorio | H37: 0 | I37: 0 | J37: 0 | K37: 0 | L37: 0 | M37: 0 | N37: 0 | O37: 0 | P37: 0 | Q37: 0 | R37: 0 | S37: 0 | T37: 0 | U37: 0 | V37: 0 | W37: 0 | X37: 0 | Y37: 0 | Z37: 0 | AA37: 0 | AB37: 0
A38: Eduardo Soto | B38: Alejandro Escobar | C38: 0 | D38: 45772 | E38: 45772 | F38: 0 | G38: Libre Compensatorio | H38: 0 | I38: 0 | J38: 0 | K38: 0 | L38: 0 | M38: 0 | N38: 0 | O38: 0 | P38: 0 | Q38: 0 | R38: 0 | S38: 0 | T38: 0 | U38: 0 | V38: 0 | W38: 0 | X38: 0 | Y38: 0 | Z38: 0 | AA38: 0 | AB38: 0
A39: Albert Riveros | B39: N/A | C39: 0 | D39: 45772 | E39: 45772 | F39: 0 | G39: Licencia Medica | H39: 0 | I39: 0 | J39: 0 | K39: 0 | L39: 0 | M39: 0 | N39: 0 | O39: 0 | P39: 0 | Q39: 0 | R39: 0 | S39: 0 | T39: 0 | U39: 0 | V39: 0 | W39: 0 | X39: 0 | Y39: 0 | Z39: 0 | AA39: 0 | AB39: 0
A40: Francisco Cuevas | B40: N/A | C40: 0 | D40: 45772 | E40: 45772 | F40: 0 | G40: Licencia Medica | H40: 0 | I40: 0 | J40: 0 | K40: 0 | L40: 0 | M40: 0 | N40: 0 | O40: 0 | P40: 0 | Q40: 0 | R40: 0 | S40: 0 | T40: 0 | U40: 0 | V40: 0 | W40: 0 | X40: 0 | Y40: 0 | Z40: 0 | AA40: 0 | AB40: 0
...

Sheet Hoja2
A1: Operador | C1: 45769 | D1: 45770 | E1: 45771 | F1: 45772 | G1: 45773 | H1: 45774 | I1: 45775 | J1: 45776 | K1: 45777 | L1: 45778 | M1: 45779 | N1: 45780 | O1: 45781 | P1: 45782
A2: Cristian Valdivia
B3: Estado | C3: =+SUMIF('Base Datos'!E:Z,Hoja2!B3) -> 0
B4: Despacho / Retiro | C4: =+SUMIF('Base Datos'!E:Z,Hoja2!B4) -> 0
B5: Entrada < 19:30 | C5: =+SUMIF('Base Datos'!E:Z,Hoja2!B5) -> 0
B6: Salida > 19:30 | C6: =+SUMIF('Base Datos'!E:Z,Hoja2!B6) -> 0
B7: Feria Semana 01 | C7: =+SUMIF('Base Datos'!E:Z,Hoja2!B7) -> 0
B8: Feria Semana 02 | C8: =+SUMIF('Base Datos'!E:Z,Hoja2!B8) -> 0
B9: Fuera Radio Normal | C9: =+SUMIF('Base Datos'!E:Z,Hoja2!B9) -> 0
B10: Fuera Radio V Región | C10: =+SUMIF('Base Datos'!E:Z,Hoja2!B10) -> 0
B11: Sabado | C11: =+SUMIF('Base Datos'!E:Z,Hoja2!B11) -> 0
B12: Domingo | C12: =+SUMIF('Base Datos'!E:Z,Hoja2!B12) -> 0
B13: Viajes Por Cliente | C13: =+SUMIF('Base Datos'!E:Z,Hoja2!B13) -> 0
B14: Sábado > 16:00 | C14: =+SUMIF('Base Datos'!E:Z,Hoja2!B14) -> 0
... B22: Fosa | C22: =+SUMIF('Base Datos'!E:Z,Hoja2!B22) -> 0
A24: Daniel Peña
B25: Estado
B26: Despacho / Retiro
B27: Entrada < 19:30
B28: Salida > 19:30
B29: Feria Semana 01
B30: Feria Semana 02
B31: Fuera Radio Normal
B32: Fuera Radio V Región
B33: Sabado
B34: Domingo
B35: Viajes Por Cliente
B36: Sábado > 16:00
... B44: Fosa
A46: Eduardo Soto
B47: Estado
B48: Despacho / Retiro
B49: Entrada < 19:30
B50: Salida > 19:30
B51: Feria Semana 01
B52: Feria Semana 02
B53: Fuera Radio Normal
B54: Fuera Radio V Región
B55: Sabado
B56: Domingo
...
